2025-04-16 15:33:42 [ERROR] w3_utils.call_contract_with_timeout:467 - Error in blockchain verification: Could not transact with/call contract function, is contract deployed correctly and chain synced?
2025-04-16 15:33:42 [ERROR] app.validate:226 - Error in /validate_token: cannot unpack non-iterable bool object
2025-04-16 15:33:42 [ERROR] app.validate:227 - Traceback (most recent call last):
  File "P:\blockchain-id-authentication\PII-Authenticator\backend\app.py", line 209, in validate
    valid, blockchain_details = verify_token(token)
    ^^^^^^^^^^^^^^^^^^^^^^^^^
TypeError: cannot unpack non-iterable bool object

2025-04-16 15:50:36 [ERROR] w3_utils.call_contract_with_timeout:467 - Error in blockchain verification: Could not transact with/call contract function, is contract deployed correctly and chain synced?
2025-04-16 15:57:21 [ERROR] w3_utils.call_contract_with_timeout:476 - Error in blockchain verification: Could not transact with/call contract function, is contract deployed correctly and chain synced?
2025-04-16 16:09:00 [ERROR] w3_utils.call_contract_with_timeout:564 - Error in blockchain verification: Could not transact with/call contract function, is contract deployed correctly and chain synced?
2025-04-16 16:10:21 [ERROR] w3_utils.call_contract_with_timeout:564 - Error in blockchain verification: Could not transact with/call contract function, is contract deployed correctly and chain synced?
2025-04-16 16:19:15 [ERROR] w3_utils.regenerate_blockchain_record:389 - Failed to regenerate blockchain record
2025-04-16 16:19:15 [ERROR] token_auth.verify_token:278 - Failed to regenerate blockchain record for token C04RL2MN8Q
2025-04-16 16:19:16 [ERROR] w3_utils.call_contract_with_timeout:631 - Error in blockchain verification: Could not transact with/call contract function, is contract deployed correctly and chain synced?
2025-04-16 16:19:20 [ERROR] w3_utils.regenerate_blockchain_record:389 - Failed to regenerate blockchain record
2025-04-16 16:19:20 [ERROR] token_auth.verify_token:278 - Failed to regenerate blockchain record for token C04RL2MN8Q
2025-04-16 16:19:21 [ERROR] w3_utils.call_contract_with_timeout:631 - Error in blockchain verification: Could not transact with/call contract function, is contract deployed correctly and chain synced?
2025-04-16 16:22:47 [ERROR] w3_utils.call_contract_with_timeout:631 - Error in blockchain verification: Could not transact with/call contract function, is contract deployed correctly and chain synced?
2025-04-16 16:23:54 [ERROR] w3_utils.regenerate_blockchain_record:389 - Failed to regenerate blockchain record
2025-04-16 16:23:54 [ERROR] token_auth.verify_token:278 - Failed to regenerate blockchain record for token BWM7YWS0CH
2025-04-16 16:23:55 [ERROR] w3_utils.call_contract_with_timeout:631 - Error in blockchain verification: Could not transact with/call contract function, is contract deployed correctly and chain synced?
2025-04-16 16:30:04 [ERROR] w3_utils.call_contract_with_timeout:725 - Error in blockchain verification: Could not transact with/call contract function, is contract deployed correctly and chain synced?
2025-04-16 16:30:12 [ERROR] w3_utils.call_contract_with_timeout:725 - Error in blockchain verification: Could not transact with/call contract function, is contract deployed correctly and chain synced?
2025-04-16 16:42:15 [ERROR] w3_utils.call_contract_with_timeout:758 - Error in blockchain verification: Could not transact with/call contract function, is contract deployed correctly and chain synced?
2025-04-16 16:44:24 [ERROR] w3_utils.call_contract_with_timeout:758 - Error in blockchain verification: Could not transact with/call contract function, is contract deployed correctly and chain synced?
2025-04-16 16:45:19 [ERROR] w3_utils.call_contract_with_timeout:758 - Error in blockchain verification: Could not transact with/call contract function, is contract deployed correctly and chain synced?
2025-04-16 16:50:05 [ERROR] w3_utils.call_contract_with_timeout:758 - Error in blockchain verification: Could not transact with/call contract function, is contract deployed correctly and chain synced?
2025-04-16 16:51:03 [ERROR] w3_utils.call_contract_with_timeout:758 - Error in blockchain verification: Could not transact with/call contract function, is contract deployed correctly and chain synced?
2025-04-16 16:51:37 [ERROR] w3_utils.call_contract_with_timeout:758 - Error in blockchain verification: Could not transact with/call contract function, is contract deployed correctly and chain synced?
2025-04-16 16:53:05 [ERROR] w3_utils.call_contract_with_timeout:758 - Error in blockchain verification: Could not transact with/call contract function, is contract deployed correctly and chain synced?
2025-04-16 16:54:17 [ERROR] w3_utils.call_contract_with_timeout:758 - Error in blockchain verification: Could not transact with/call contract function, is contract deployed correctly and chain synced?
2025-04-16 16:54:59 [ERROR] w3_utils.call_contract_with_timeout:758 - Error in blockchain verification: Could not transact with/call contract function, is contract deployed correctly and chain synced?
2025-04-16 16:55:19 [ERROR] w3_utils.call_contract_with_timeout:758 - Error in blockchain verification: Could not transact with/call contract function, is contract deployed correctly and chain synced?
2025-04-16 16:55:36 [ERROR] w3_utils.call_contract_with_timeout:758 - Error in blockchain verification: Could not transact with/call contract function, is contract deployed correctly and chain synced?
2025-04-16 16:56:06 [ERROR] w3_utils.call_contract_with_timeout:758 - Error in blockchain verification: Could not transact with/call contract function, is contract deployed correctly and chain synced?
2025-04-16 16:58:22 [ERROR] w3_utils.call_contract_with_timeout:758 - Error in blockchain verification: Could not transact with/call contract function, is contract deployed correctly and chain synced?
2025-04-16 17:10:13 [ERROR] w3_utils.call_contract_with_timeout:758 - Error in blockchain verification: Could not transact with/call contract function, is contract deployed correctly and chain synced?
2025-04-16 17:10:19 [ERROR] w3_utils.call_contract_with_timeout:758 - Error in blockchain verification: Could not transact with/call contract function, is contract deployed correctly and chain synced?
2025-04-16 17:10:29 [ERROR] w3_utils.call_contract_with_timeout:758 - Error in blockchain verification: Could not transact with/call contract function, is contract deployed correctly and chain synced?
2025-04-16 17:12:36 [ERROR] w3_utils.call_contract_with_timeout:758 - Error in blockchain verification: Could not transact with/call contract function, is contract deployed correctly and chain synced?
2025-04-16 17:14:01 [ERROR] w3_utils.call_contract_with_timeout:758 - Error in blockchain verification: Could not transact with/call contract function, is contract deployed correctly and chain synced?
2025-04-16 17:17:19 [ERROR] w3_utils.call_contract_with_timeout:758 - Error in blockchain verification: Could not transact with/call contract function, is contract deployed correctly and chain synced?
2025-04-16 17:48:41 [ERROR] w3_utils.call_contract_with_timeout:758 - Error in blockchain verification: Could not transact with/call contract function, is contract deployed correctly and chain synced?
2025-04-17 08:07:37 [ERROR] w3_utils.call_contract_with_timeout:758 - Error in blockchain verification: Could not transact with/call contract function, is contract deployed correctly and chain synced?
2025-04-17 08:07:45 [ERROR] w3_utils.call_contract_with_timeout:758 - Error in blockchain verification: Could not transact with/call contract function, is contract deployed correctly and chain synced?
2025-04-17 08:09:56 [ERROR] w3_utils.call_contract_with_timeout:758 - Error in blockchain verification: Could not transact with/call contract function, is contract deployed correctly and chain synced?
2025-04-21 10:13:12 [ERROR] app.upload_document:624 - Error uploading document: upload_to_filebase() missing 1 required positional argument: 'file_data'
2025-04-21 10:26:11 [ERROR] app.upload_document:624 - Error uploading document: upload_to_filebase() missing 1 required positional argument: 'file_data'
2025-04-21 10:29:34 [ERROR] app.upload_document:624 - Error uploading document: upload_to_filebase() missing 1 required positional argument: 'file_data'
2025-04-21 10:34:08 [ERROR] app.upload_document:624 - Error uploading document: upload_to_filebase() missing 1 required positional argument: 'file_data'
2025-04-21 11:07:59 [ERROR] app.upload_document:624 - Error uploading document: upload_to_filebase() missing 1 required positional argument: 'file_data'
2025-04-21 13:54:39 [ERROR] app.handle_exception:153 - Unhandled exception: 404 Not Found: The requested URL was not found on the server. If you entered the URL manually please check your spelling and try again.
2025-04-21 13:54:39 [ERROR] app.handle_exception:154 - Traceback (most recent call last):
  File "C:\Users\prajw\AppData\Local\Programs\Python\Python313\Lib\site-packages\flask\app.py", line 1484, in full_dispatch_request
    rv = self.dispatch_request()
  File "C:\Users\prajw\AppData\Local\Programs\Python\Python313\Lib\site-packages\flask\app.py", line 1458, in dispatch_request
    self.raise_routing_exception(req)
    ~~~~~~~~~~~~~~~~~~~~~~~~~~~~^^^^^
  File "C:\Users\prajw\AppData\Local\Programs\Python\Python313\Lib\site-packages\flask\app.py", line 1440, in raise_routing_exception
    raise request.routing_exception  # type: ignore
    ^^^^^^^^^^^^^^^^^^^^^^^^^^^^^^^
  File "C:\Users\prajw\AppData\Local\Programs\Python\Python313\Lib\site-packages\flask\ctx.py", line 353, in match_request
    result = self.url_adapter.match(return_rule=True)  # type: ignore
  File "C:\Users\prajw\AppData\Local\Programs\Python\Python313\Lib\site-packages\werkzeug\routing\map.py", line 629, in match
    raise NotFound() from None
werkzeug.exceptions.NotFound: 404 Not Found: The requested URL was not found on the server. If you entered the URL manually please check your spelling and try again.

2025-04-21 13:54:43 [ERROR] app.handle_exception:153 - Unhandled exception: 404 Not Found: The requested URL was not found on the server. If you entered the URL manually please check your spelling and try again.
2025-04-21 13:54:43 [ERROR] app.handle_exception:154 - Traceback (most recent call last):
  File "C:\Users\prajw\AppData\Local\Programs\Python\Python313\Lib\site-packages\flask\app.py", line 1484, in full_dispatch_request
    rv = self.dispatch_request()
  File "C:\Users\prajw\AppData\Local\Programs\Python\Python313\Lib\site-packages\flask\app.py", line 1458, in dispatch_request
    self.raise_routing_exception(req)
    ~~~~~~~~~~~~~~~~~~~~~~~~~~~~^^^^^
  File "C:\Users\prajw\AppData\Local\Programs\Python\Python313\Lib\site-packages\flask\app.py", line 1440, in raise_routing_exception
    raise request.routing_exception  # type: ignore
    ^^^^^^^^^^^^^^^^^^^^^^^^^^^^^^^
  File "C:\Users\prajw\AppData\Local\Programs\Python\Python313\Lib\site-packages\flask\ctx.py", line 353, in match_request
    result = self.url_adapter.match(return_rule=True)  # type: ignore
  File "C:\Users\prajw\AppData\Local\Programs\Python\Python313\Lib\site-packages\werkzeug\routing\map.py", line 629, in match
    raise NotFound() from None
werkzeug.exceptions.NotFound: 404 Not Found: The requested URL was not found on the server. If you entered the URL manually please check your spelling and try again.

2025-04-22 09:55:32 [ERROR] app.handle_exception:153 - Unhandled exception: 404 Not Found: The requested URL was not found on the server. If you entered the URL manually please check your spelling and try again.
2025-04-22 09:55:32 [ERROR] app.handle_exception:154 - Traceback (most recent call last):
  File "C:\Users\prajw\AppData\Local\Programs\Python\Python313\Lib\site-packages\flask\app.py", line 1484, in full_dispatch_request
    rv = self.dispatch_request()
  File "C:\Users\prajw\AppData\Local\Programs\Python\Python313\Lib\site-packages\flask\app.py", line 1458, in dispatch_request
    self.raise_routing_exception(req)
    ~~~~~~~~~~~~~~~~~~~~~~~~~~~~^^^^^
  File "C:\Users\prajw\AppData\Local\Programs\Python\Python313\Lib\site-packages\flask\app.py", line 1440, in raise_routing_exception
    raise request.routing_exception  # type: ignore
    ^^^^^^^^^^^^^^^^^^^^^^^^^^^^^^^
  File "C:\Users\prajw\AppData\Local\Programs\Python\Python313\Lib\site-packages\flask\ctx.py", line 353, in match_request
    result = self.url_adapter.match(return_rule=True)  # type: ignore
  File "C:\Users\prajw\AppData\Local\Programs\Python\Python313\Lib\site-packages\werkzeug\routing\map.py", line 629, in match
    raise NotFound() from None
werkzeug.exceptions.NotFound: 404 Not Found: The requested URL was not found on the server. If you entered the URL manually please check your spelling and try again.

